Workbook

Sheet Portfolios
A1: Utility Name | B1: Utility Number | C1: Unit ID | D1: Location | E1: Unit Type | F1: Max Capacity (MW) | G1: Avg. Capacity Factor | H1: Fuel Cost ($/MW-hr) | I1: Variable O&M Costs ($/MW-hr) | J1: Total Incremental Cost ($/MW-hr) | K1: Fixed Daily O&M Costs ($/day) | L1: Start-up Costs ($/start-up)
A2: Rogue Renewables | B2: 1 | C2: 11 | D2: West | E2: Offshore Wind | F2: 250 | G2: 0.7 | H2: 0 | I2: 2 | J2: 2 | K2: 2000 | L2: 0
B3: 1 | C3: 12 | D3: West | E3: Offshore Wind | F3: 250 | G3: 0.7 | H3: 0 | I3: 2 | J3: 2 | K3: 2000 | L3: 0
B4: 1 | C4: 13 | D4: West | E4: Geothermal | F4: 600 | G4: 1 | H4: 1.5 | I4: 4.5 | J4: 6 | K4: 500 | L4: 250
B5: 1 | C5: 14 | D5: West | E5: Geothermal | F5: 600 | G5: 1 | H5: 1.5 | I5: 6.5 | J5: 8 | K5: 500 | L5: 250
B6: 1 | C6: 15 | D6: West | E6: Geothermal | F6: 475 | G6: 1 | H6: 1.5 | I6: 7 | J6: 8.5 | K6: 500 | L6: 250
A7: Rose City Spark | B7: 2 | C7: 21 | D7: West | E7: Hydro | F7: 145 | G7: 1 | H7: 0 | I7: 3.5 | J7: 3.5 | K7: 500 | L7: 0
B8: 2 | C8: 22 | D8: West | E8: Hydro | F8: 145 | G8: 1 | H8: 0 | I8: 3.5 | J8: 3.5 | K8: 500 | L8: 0
B9: 2 | C9: 23 | D9: West | E9: Natural Gas | F9: 750 | G9: 1 | H9: 32 | I9: 4 | J9: 36 | K9: 1000 | L9: 1500
B10: 2 | C10: 24 | D10: West | E10: Natural Gas | F10: 720 | G10: 1 | H10: 37 | I10: 4 | J10: 41 | K10: 1000 | L10: 1750
B11: 2 | C11: 25 | D11: West | E11: Natural Gas | F11: 650 | G11: 1 | H11: 52 | I11: 4 | J11: 56 | K11: 2000 | L11: 2000
B12: 2 | C12: 26 | D12: West | E12: Natural Gas | F12: 600 | G12: 1 | H12: 54 | I12: 4 | J12: 58 | K12: 2000 | L12: 2000
B13: 2 | C13: 27 | D13: West | E13: Solar | F13: 540 | G13: 0.6 | H13: 0 | I13: 0.5 | J13: 0.5 | K13: 250 | L13: 0
A14: Cascadia Generation | B14: 3 | C14: 31 | D14: West | E14: Natural Gas | F14: 400 | G14: 1 | H14: 26.5 | I14: 5 | J14: 31.5 | K14: 1000 | L14: 750
B15: 3 | C15: 32 | D15: West | E15: Solar | F15: 600 | G15: 0.6 | H15: 0 | I15: 2 | J15: 2 | K15: 750 | L15: 0
B16: 3 | C16: 33 | D16: West | E16: Solar | F16: 600 | G16: 0.6 | H16: 0 | I16: 2 | J16: 2 | K16: 750 | L16: 0
B17: 3 | C17: 34 | D17: West | E17: Solar | F17: 475 | G17: 0.6 | H17: 0 | I17: 2.5 | J17: 2.5 | K17: 250 | L17: 0
B18: 3 | C18: 35 | D18: West | E18: Solar | F18: 350 | G18: 0.6 | H18: 0 | I18: 2.5 | J18: 2.5 | K18: 250 | L18: 0
B19: 3 | C19: 36 | D19: West | E19: Onshore Wind | F19: 375 | G19: 0.35 | H19: 0 | I19: 3.8 | J19: 3.8 | K19: 750 | L19: 0
B20: 3 | C20: 37 | D20: West | E20: Onshore Wind | F20: 375 | G20: 0.35 | H20: 0 | I20: 4 | J20: 4 | K20: 750 | L20: 0
B21: 3 | C21: 38 | D21: West | E21: Onshore Wind | F21: 375 | G21: 0.35 | H21: 0 | I21: 4 | J21: 4 | K21: 750 | L21: 0
A22: San Juan Power & Light | B22: 4 | C22: 41 | D22: West | E22: Offshore Wind | F22: 820 | G22: 0.7 | H22: 0 | I22: 1.5 | J22: 1.5 | K22: 2500 | L22: 0
B23: 4 | C23: 42 | D23: West | E23: Offshore Wind | F23: 780 | G23: 0.7 | H23: 0 | I23: 1.5 | J23: 1.5 | K23: 2000 | L23: 0
B24: 4 | C24: 43 | D24: West | E24: Offshore Wind | F24: 700 | G24: 0.7 | H24: 0 | I24: 1.5 | J24: 1.5 | K24: 2000 | L24: 0
B25: 4 | C25: 44 | D25: West | E25: Wave | F25: 425 | G25: 0.9 | H25: 0 | I25: 3 | J25: 3 | K25: 1250 | L25: 0
B26: 4 | C26: 45 | D26: West | E26: Wave | F26: 425 | G26: 0.9 | H26: 0 | I26: 3 | J26: 3 | K26: 1250 | L26: 0
B27: 4 | C27: 46 | D27: West | E27: Natural Gas | F27: 225 | G27: 1 | H27: 35 | I27: 3.5 | J27: 38.5 | K27: 1500 | L27: 1000
B28: 4 | C28: 47 | D28: West | E28: Natural Gas | F28: 175 | G28: 1 | H28: 38 | I28: 3.5 | J28: 41.5 | K28: 3500 | L28: 1500
A29: Central Washington Power | B29: 5 | C29: 51 | D29: East | E29: Nuclear | F29: 1100 | G29: 1 | H29: 10 | I29: 0.5 | J29: 10.5 | K29: 2000 | L29: 7500
B30: 5 | C30: 52 | D30: East | E30: Nuclear | F30: 950 | G30: 1 | H30: 10 | I30: 0.5 | J30: 10.5 | K30: 2000 | L30: 7500
B31: 5 | C31: 53 | D31: East | E31: Hydro | F31: 650 | G31: 1 | H31: 0 | I31: 1.5 | J31: 1.5 | K31: 750 | L31: 0
B32: 5 | C32: 54 | D32: East | E32: Hydro | F32: 450 | G32: 1 | H32: 0 | I32: 1.5 | J32: 1.5 | K32: 750 | L32: 0
B33: 5 | C33: 55 | D33: East | E33: Onshore Wind | F33: 400 | G33: 0.35 | H33: 0 | I33: 3.5 | J33: 3.5 | K33: 250 | L33: 0
A34: Snake River Energy | B34: 6 | C34: 61 | D34: East | E34: Solar | F34: 950 | G34: 0.6 | H34: 0 | I34: 0.5 | J34: 0.5 | K34: 500 | L34: 0
B35: 6 | C35: 62 | D35: East | E35: Solar | F35: 875 | G35: 0.6 | H35: 0 | I35: 2.5 | J35: 2.5 | K35: 500 | L35: 0
B36: 6 | C36: 63 | D36: East | E36: Hydro | F36: 300 | G36: 1 | H36: 0 | I36: 2.5 | J36: 2.5 | K36: 1250 | L36: 0
B37: 6 | C37: 64 | D37: East | E37: Hydro | F37: 225 | G37: 1 | H37: 0 | I37: 3 | J37: 3 | K37: 1000 | L37: 0
B38: 6 | C38: 65 | D38: East | E38: Natural Gas | F38: 650 | G38: 1 | H38: 34 | I38: 0.5 | J38: 34.5 | K38: 1500 | L38: 1000
B39: 6 | C39: 66 | D39: East | E39: Natural Gas | F39: 550 | G39: 1 | H39: 37 | I39: 0.5 | J39: 37.5 | K39: 1750 | L39: 1250
A40: Garrison Heavy Industries | B40: 7 | C40: 71 | D40: East | E40: Coal | F40: 1625 | G40: 1 | H40: 21 | I40: 22.5 | J40: 43.5 | K40: 2500 | L40: 3000
...

Sheet Locations

Sheet System Load
G1: 1 | H1: 2 | I1: 3 | J1: 4
G2: 6 | H2: 7 | I2: 8 | J2: 9 | K2: <- Generation Codes
B3: Day | C3: Hour | D3: West Load (MW) | E3: East Load (MW) | F3: Transmission Limit | G3: Offshore Wind | H3: Onshore Wind | I3: Solar | J3: Wave
A4: 1 | B4: 1 | C4: 11 | D4: 7288.8344 | E4: 3916.4117 | F4: 9999 | G4: 0.54509912 | H4: 0.055797368 | I4: 0.44438288 | J4: 0.87775556
A5: 2 | B5: 1 | C5: 12 | D5: 4180.4884 | E5: 1998.9207 | F5: 9999 | G5: 1 | H5: 0.70863205 | I5: 1 | J5: 0.91193024
A6: 3 | B6: 1 | C6: 13 | D6: 1611.0052 | E6: 6161.0891 | F6: 9999 | G6: 0.59113402 | H6: 0.4494775 | I6: 0.79116936 | J6: 0.86509151 | P6: Generation Codes
A7: 4 | B7: 1 | C7: 14 | D7: 7446.948 | E7: 5172.0742 | F7: 9999 | G7: 0.21486811 | H7: 0.11977743 | I7: 0.23501107 | J7: 0.92793646 | P7: Coal | Q7: 1
P8: Geothermal | Q8: 2
D9: RANDOM - WILL NOT BE ACTUAL FIRST DAY LOAD OR CAPACITY FACTORS | M9: Load Forecast | P9: Hydro | Q9: 3
M10: West Load (MW) | N10: East Load (MW) | P10: Natural Gas | Q10: 4
M11: 5000 | N11: 4000 | P11: Nuclear | Q11: 5
M12: 3000 | N12: 2000 | P12: Offshore Wind | Q12: 6
M13: 2700 | N13: 5800 | P13: Onshore Wind | Q13: 7
M14: 7200 | N14: 3600 | P14: Solar | Q14: 8
P15: Wave | Q15: 9
M17: Actual Load | P17: Capacity Factors
M18: West Load (MW) | N18: East Load (MW) | P18: Offshore Wind | Q18: Onshore Wind | R18: Solar | S18: Wave
M19: =M11+NORMINV(RAND(),0,1000) -> 2812.9755 | N19: =N11+NORMINV(RAND(),0,1000) -> 4985.5555 | P19: =MIN(($R$27*(-LN(1-RAND()))^(1/$Q$27)),1) -> 0.42256555 | Q19: =MIN(($R$26*(-LN(1-RAND()))^(1/$Q$26)),1) -> 0.36248381 | R19: =NORMINV(RAND(),0.45,0.45*0.06) -> 0.44945293 | S19: =MIN(NORMINV(RAND(),0.9,0.9*0.06),1) -> 0.88131452
M20: =M12+NORMINV(RAND(),0,1000) -> 935.36903 | N20: =N12+NORMINV(RAND(),0,1000) -> 1902.2661 | P20: =MIN(($R$27*(-LN(1-RAND()))^(1/$Q$27)),1) -> 0.23597138 | Q20: =MIN(($R$26*(-LN(1-RAND()))^(1/$Q$26)),1) -> 0.44145419 | R20: =MIN(NORMINV(RAND(),0.95,0.95*0.06),1) -> 0.97053034 | S20: =MIN(NORMINV(RAND(),0.9,0.9*0.06),1) -> 0.8880039
M21: =M13+NORMINV(RAND(),0,1000) -> 4106.8483 | N21: =N13+NORMINV(RAND(),0,1000) -> 3992.0742 | P21: =MIN(($R$27*(-LN(1-RAND()))^(1/$Q$27)),1) -> 0.39234258 | Q21: =MIN(($R$26*(-LN(1-RAND()))^(1/$Q$26)),1) -> 0.048922618 | R21: =NORMINV(RAND(),0.75,0.75*0.06) -> 0.78146845 | S21: =MIN(NORMINV(RAND(),0.9,0.9*0.06),1) -> 0.90335823
M22: =M14+NORMINV(RAND(),0,1000) -> 7532.479 | N22: =N14+NORMINV(RAND(),0,1000) -> 2527.9904 | P22: =MIN(($R$27*(-LN(1-RAND()))^(1/$Q$27)),1) -> 1 | Q22: =MIN(($R$26*(-LN(1-RAND()))^(1/$Q$26)),1) -> 0.43221882 | R22: =NORMINV(RAND(),0.25,0.25*0.06) -> 0.22526564 | S22: =MIN(NORMINV(RAND(),0.9,0.9*0.06),1) -> 0.96375551
P24: Wind Weibull Distribution Paramaters
Q25: alpha | R25: beta
P26: Onshore | Q26: 1.8 | R26: 0.3
P27: Offshore | Q27: 1.8 | R27: 0.7

Sheet Bids
G2: Hour 1 | I2: Hour 2 | K2: Hour 3 | M2: Hour 4
A3: Utility Name | B3: Utility Number | C3: Unit ID | D3: Location | E3: Unit Type | F3: Max Capacity (MW) | G3: Bid Capacity (MW) | H3: Bid Price ($/MW-hr) | I3: Bid Capacity (MW) | J3: Bid Price ($/MW-hr) | K3: Bid Capacity (MW) | L3: Bid Price ($/MW-hr) | M3: Bid Capacity (MW) | N3: Bid Price ($/MW-hr) | P3: Day | Q3: 1
A4: Rogue Renewables | B4: 1 | C4: 11 | D4: West | E4: =Portfolios!E2 -> Offshore Wind | F4: =Portfolios!F2 -> 250
B5: 1 | C5: 12 | D5: West | E5: =Portfolios!E3 -> Offshore Wind | F5: =Portfolios!F3 -> 250
B6: 1 | C6: 13 | D6: West | E6: =Portfolios!E4 -> Geothermal | F6: =Portfolios!F4 -> 600
B7: 1 | C7: 14 | D7: West | E7: =Portfolios!E5 -> Geothermal | F7: =Portfolios!F5 -> 600
B8: 1 | C8: 15 | D8: West | E8: =Portfolios!E6 -> Geothermal | F8: =Portfolios!F6 -> 475
A9: Rose City Spark | B9: 2 | C9: 21 | D9: West | E9: =Portfolios!E7 -> Hydro | F9: =Portfolios!F7 -> 145
B10: 2 | C10: 22 | D10: West | E10: =Portfolios!E8 -> Hydro | F10: =Portfolios!F8 -> 145
B11: 2 | C11: 23 | D11: West | E11: =Portfolios!E9 -> Natural Gas | F11: =Portfolios!F9 -> 750
B12: 2 | C12: 24 | D12: West | E12: =Portfolios!E10 -> Natural Gas | F12: =Portfolios!F10 -> 720
B13: 2 | C13: 25 | D13: West | E13: =Portfolios!E11 -> Natural Gas | F13: =Portfolios!F11 -> 650
B14: 2 | C14: 26 | D14: West | E14: =Portfolios!E12 -> Natural Gas | F14: =Portfolios!F12 -> 600
B15: 2 | C15: 27 | D15: West | E15: =Portfolios!E13 -> Solar | F15: =Portfolios!F13 -> 540
A16: Cascadia Generation | B16: 3 | C16: 31 | D16: West | E16: =Portfolios!E14 -> Natural Gas | F16: =Portfolios!F14 -> 400
B17: 3 | C17: 32 | D17: West | E17: =Portfolios!E15 -> Solar | F17: =Portfolios!F15 -> 600
B18: 3 | C18: 33 | D18: West | E18: =Portfolios!E16 -> Solar | F18: =Portfolios!F16 -> 600
B19: 3 | C19: 34 | D19: West | E19: =Portfolios!E17 -> Solar | F19: =Portfolios!F17 -> 475
B20: 3 | C20: 35 | D20: West | E20: =Portfolios!E18 -> Solar | F20: =Portfolios!F18 -> 350
B21: 3 | C21: 36 | D21: West | E21: =Portfolios!E19 -> Onshore Wind | F21: =Portfolios!F19 -> 375
B22: 3 | C22: 37 | D22: West | E22: =Portfolios!E20 -> Onshore Wind | F22: =Portfolios!F20 -> 375
B23: 3 | C23: 38 | D23: West | E23: =Portfolios!E21 -> Onshore Wind | F23: =Portfolios!F21 -> 375
A24: San Juan Power & Light | B24: 4 | C24: 41 | D24: West | E24: =Portfolios!E22 -> Offshore Wind | F24: =Portfolios!F22 -> 820
B25: 4 | C25: 42 | D25: West | E25: =Portfolios!E23 -> Offshore Wind | F25: =Portfolios!F23 -> 780
B26: 4 | C26: 43 | D26: West | E26: =Portfolios!E24 -> Offshore Wind | F26: =Portfolios!F24 -> 700
B27: 4 | C27: 44 | D27: West | E27: =Portfolios!E25 -> Wave | F27: =Portfolios!F25 -> 425
B28: 4 | C28: 45 | D28: West | E28: =Portfolios!E26 -> Wave | F28: =Portfolios!F26 -> 425
B29: 4 | C29: 46 | D29: West | E29: =Portfolios!E27 -> Natural Gas | F29: =Portfolios!F27 -> 225
B30: 4 | C30: 47 | D30: West | E30: =Portfolios!E28 -> Natural Gas | F30: =Portfolios!F28 -> 175
A31: Central Washington Power | B31: 5 | C31: 51 | D31: East | E31: =Portfolios!E29 -> Nuclear | F31: =Portfolios!F29 -> 1100
B32: 5 | C32: 52 | D32: East | E32: =Portfolios!E30 -> Nuclear | F32: =Portfolios!F30 -> 950
B33: 5 | C33: 53 | D33: East | E33: =Portfolios!E31 -> Hydro | F33: =Portfolios!F31 -> 650
B34: 5 | C34: 54 | D34: East | E34: =Portfolios!E32 -> Hydro | F34: =Portfolios!F32 -> 450
B35: 5 | C35: 55 | D35: East | E35: =Portfolios!E33 -> Onshore Wind | F35: =Portfolios!F33 -> 400
A36: Snake River Energy | B36: 6 | C36: 61 | D36: East | E36: =Portfolios!E34 -> Solar | F36: =Portfolios!F34 -> 950
B37: 6 | C37: 62 | D37: East | E37: =Portfolios!E35 -> Solar | F37: =Portfolios!F35 -> 875
B38: 6 | C38: 63 | D38: East | E38: =Portfolios!E36 -> Hydro | F38: =Portfolios!F36 -> 300
B39: 6 | C39: 64 | D39: East | E39: =Portfolios!E37 -> Hydro | F39: =Portfolios!F37 -> 225
B40: 6 | C40: 65 | D40: East | E40: =Portfolios!E38 -> Natural Gas | F40: =Portfolios!F38 -> 650
B41: 6 | C41: 66 | D41: East | E41: =Portfolios!E39 -> Natural Gas | F41: =Portfolios!F39 -> 550
...

Sheet Renewable Dispatch
T1: (random, for demonstration, not actuals)
A2: Day: | B2: =Bids!Q3 -> 1 | J2: Capacity Bid (MW) | O2: Bid Price ($/MW-hr) | T2: Capacity Factor | Y2: Effective Capacity Bid
I3: Hour Code: | J3: =$B$2*10+1 -> 11 | K3: =$B$2*10+2 -> 12 | L3: =$B$2*10+3 -> 13 | M3: =$B$2*10+4 -> 14 | O3: =$B$2*10+1 -> 11 | P3: =$B$2*10+2 -> 12 | Q3: =$B$2*10+3 -> 13 | R3: =$B$2*10+4 -> 14 | T3: =$B$2*10+1 -> 11 | U3: =$B$2*10+2 -> 12 | V3: =$B$2*10+3 -> 13 | W3: =$B$2*10+4 -> 14 | Y3: =$B$2*10+1 -> 11 | Z3: =$B$2*10+2 -> 12 | AA3: =$B$2*10+3 -> 13 | AB3: =$B$2*10+4 -> 14
A4: Utility Name | B4: Utility Number | C4: Unit ID | D4: Location | E4: Unit Type | F4: Unit Type Code | G4: Max Capacity (MW)
A5: Rogue Renewables | B5: 1 | C5: 11 | D5: West | E5: =Portfolios!E2 -> Offshore Wind | F5: =_xlfn.XLOOKUP(E5,'System Load'!$P$7:$P$15,'System Load'!$Q$7:$Q$15) -> 6 | G5: =Portfolios!F2 -> 250 | J5: =Bids!G4 -> 0 | K5: =Bids!I4 -> 0 | L5: =Bids!K4 -> 0 | M5: =Bids!M4 -> 0 | O5: =Bids!H4+RAND()/100 -> 0.0096318314 | P5: =Bids!J4+RAND()/100 -> 0.0024361704 | Q5: =Bids!L4+RAND()/100 -> 0.0090941817 | R5: =Bids!N4+RAND()/100 -> 0.0089701529 | T5: {=IF($F5<=5,1,INDEX('System Load'!$G$4:$J$35,_xlfn.XLOOKUP('Renewable Dispatch'!T$3,'System Load'!$C$4:$C$35,'System Load'!$A$4:$A$35),_xlfn.XLOOKUP($F5,'System Load'!$G$2:$J$2,'System Load'!$G$1:$J$1)))} -> 0.54509912 | U5: {=IF($F5<=5,1,INDEX('System Load'!$G$4:$J$35,_xlfn.XLOOKUP('Renewable Dispatch'!U$3,'System Load'!$C$4:$C$35,'System Load'!$A$4:$A$35),_xlfn.XLOOKUP($F5,'System Load'!$G$2:$J$2,'System Load'!$G$1:$J$1)))} -> 1 | V5: {=IF($F5<=5,1,INDEX('System Load'!$G$4:$J$35,_xlfn.XLOOKUP('Renewable Dispatch'!V$3,'System Load'!$C$4:$C$35,'System Load'!$A$4:$A$35),_xlfn.XLOOKUP($F5,'System Load'!$G$2:$J$2,'System Load'!$G$1:$J$1)))} -> 0.59113402 | W5: {=IF($F5<=5,1,INDEX('System Load'!$G$4:$J$35,_xlfn.XLOOKUP('Renewable Dispatch'!W$3,'System Load'!$C$4:$C$35,'System Load'!$A$4:$A$35),_xlfn.XLOOKUP($F5,'System Load'!$G$2:$J$2,'System Load'!$G$1:$J$1)))} -> 0.21486811 | Y5: = minimum(Bid, Available Capacity)
B6: 1 | C6: 12 | D6: West | E6: =Portfolios!E3 -> Offshore Wind | F6: =_xlfn.XLOOKUP(E6,'System Load'!$P$7:$P$15,'System Load'!$Q$7:$Q$15) -> 6 | G6: =Portfolios!F3 -> 250 | J6: =Bids!G5 -> 0 | K6: =Bids!I5 -> 0 | L6: =Bids!K5 -> 0 | M6: =Bids!M5 -> 0 | O6: =Bids!H5+RAND()/100 -> 0.0035883286 | P6: =Bids!J5+RAND()/100 -> 0.0034824346 | Q6: =Bids!L5+RAND()/100 -> 0.0055771957 | R6: =Bids!N5+RAND()/100 -> 0.0060237748 | T6: {=IF($F6<=5,1,INDEX('System Load'!$G$4:$J$35,_xlfn.XLOOKUP('Renewable Dispatch'!T$3,'System Load'!$C$4:$C$35,'System Load'!$A$4:$A$35),_xlfn.XLOOKUP($F6,'System Load'!$G$2:$J$2,'System Load'!$G$1:$J$1)))} -> 0.54509912 | U6: {=IF($F6<=5,1,INDEX('System Load'!$G$4:$J$35,_xlfn.XLOOKUP('Renewable Dispatch'!U$3,'System Load'!$C$4:$C$35,'System Load'!$A$4:$A$35),_xlfn.XLOOKUP($F6,'System Load'!$G$2:$J$2,'System Load'!$G$1:$J$1)))} -> 1 | V6: {=IF($F6<=5,1,INDEX('System Load'!$G$4:$J$35,_xlfn.XLOOKUP('Renewable Dispatch'!V$3,'System Load'!$C$4:$C$35,'System Load'!$A$4:$A$35),_xlfn.XLOOKUP($F6,'System Load'!$G$2:$J$2,'System Load'!$G$1:$J$1)))} -> 0.59113402 | W6: {=IF($F6<=5,1,INDEX('System Load'!$G$4:$J$35,_xlfn.XLOOKUP('Renewable Dispatch'!W$3,'System Load'!$C$4:$C$35,'System Load'!$A$4:$A$35),_xlfn.XLOOKUP($F6,'System Load'!$G$2:$J$2,'System Load'!$G$1:$J$1)))} -> 0.21486811
B7: 1 | C7: 13 | D7: West | E7: =Portfolios!E4 -> Geothermal | F7: =_xlfn.XLOOKUP(E7,'System Load'!$P$7:$P$15,'System Load'!$Q$7:$Q$15) -> 2 | G7: =Portfolios!F4 -> 600 | J7: =Bids!G6 -> 0 | K7: =Bids!I6 -> 0 | L7: =Bids!K6 -> 0 | M7: =Bids!M6 -> 0 | O7: =Bids!H6+RAND()/100 -> 0.0011145573 | P7: =Bids!J6+RAND()/100 -> 0.0027178321 | Q7: =Bids!L6+RAND()/100 -> 0.001230963 | R7: =Bids!N6+RAND()/100 -> 0.0020599594 | T7: {=IF($F7<=5,1,INDEX('System Load'!$G$4:$J$35,_xlfn.XLOOKUP('Renewable Dispatch'!T$3,'System Load'!$C$4:$C$35,'System Load'!$A$4:$A$35),_xlfn.XLOOKUP($F7,'System Load'!$G$2:$J$2,'System Load'!$G$1:$J$1)))} -> 1 | U7: {=IF($F7<=5,1,INDEX('System Load'!$G$4:$J$35,_xlfn.XLOOKUP('Renewable Dispatch'!U$3,'System Load'!$C$4:$C$35,'System Load'!$A$4:$A$35),_xlfn.XLOOKUP($F7,'System Load'!$G$2:$J$2,'System Load'!$G$1:$J$1)))} -> 1 | V7: {=IF($F7<=5,1,INDEX('System Load'!$G$4:$J$35,_xlfn.XLOOKUP('Renewable Dispatch'!V$3,'System Load'!$C$4:$C$35,'System Load'!$A$4:$A$35),_xlfn.XLOOKUP($F7,'System Load'!$G$2:$J$2,'System Load'!$G$1:$J$1)))} -> 1 | W7: {=IF($F7<=5,1,INDEX('System Load'!$G$4:$J$35,_xlfn.XLOOKUP('Renewable Dispatch'!W$3,'System Load'!$C$4:$C$35,'System Load'!$A$4:$A$35),_xlfn.XLOOKUP($F7,'System Load'!$G$2:$J$2,'System Load'!$G$1:$J$1)))} -> 1
B8: 1 | C8: 14 | D8: West | E8: =Portfolios!E5 -> Geothermal | F8: =_xlfn.XLOOKUP(E8,'System Load'!$P$7:$P$15,'System Load'!$Q$7:$Q$15) -> 2 | G8: =Portfolios!F5 -> 600 | J8: =Bids!G7 -> 0 | K8: =Bids!I7 -> 0 | L8: =Bids!K7 -> 0 | M8: =Bids!M7 -> 0 | O8: =Bids!H7+RAND()/100 -> 0.0037627597 | P8: =Bids!J7+RAND()/100 -> 0.001868525 | Q8: =Bids!L7+RAND()/100 -> 0.0062003013 | R8: =Bids!N7+RAND()/100 -> 0.0039322138 | T8: {=IF($F8<=5,1,INDEX('System Load'!$G$4:$J$35,_xlfn.XLOOKUP('Renewable Dispatch'!T$3,'System Load'!$C$4:$C$35,'System Load'!$A$4:$A$35),_xlfn.XLOOKUP($F8,'System Load'!$G$2:$J$2,'System Load'!$G$1:$J$1)))} -> 1 | U8: {=IF($F8<=5,1,INDEX('System Load'!$G$4:$J$35,_xlfn.XLOOKUP('Renewable Dispatch'!U$3,'System Load'!$C$4:$C$35,'System Load'!$A$4:$A$35),_xlfn.XLOOKUP($F8,'System Load'!$G$2:$J$2,'System Load'!$G$1:$J$1)))} -> 1 | V8: {=IF($F8<=5,1,INDEX('System Load'!$G$4:$J$35,_xlfn.XLOOKUP('Renewable Dispatch'!V$3,'System Load'!$C$4:$C$35,'System Load'!$A$4:$A$35),_xlfn.XLOOKUP($F8,'System Load'!$G$2:$J$2,'System Load'!$G$1:$J$1)))} -> 1 | W8: {=IF($F8<=5,1,INDEX('System Load'!$G$4:$J$35,_xlfn.XLOOKUP('Renewable Dispatch'!W$3,'System Load'!$C$4:$C$35,'System Load'!$A$4:$A$35),_xlfn.XLOOKUP($F8,'System Load'!$G$2:$J$2,'System Load'!$G$1:$J$1)))} -> 1
B9: 1 | C9: 15 | D9: West | E9: =Portfolios!E6 -> Geothermal | F9: =_xlfn.XLOOKUP(E9,'System Load'!$P$7:$P$15,'System Load'!$Q$7:$Q$15) -> 2 | G9: =Portfolios!F6 -> 475 | J9: =Bids!G8 -> 0 | K9: =Bids!I8 -> 0 | L9: =Bids!K8 -> 0 | M9: =Bids!M8 -> 0 | O9: =Bids!H8+RAND()/100 -> 0.0031073861 | P9: =Bids!J8+RAND()/100 -> 0.0025042714 | Q9: =Bids!L8+RAND()/100 -> 0.0090889925 | R9: =Bids!N8+RAND()/100 -> 0.00068736048 | T9: {=IF($F9<=5,1,INDEX('System Load'!$G$4:$J$35,_xlfn.XLOOKUP('Renewable Dispatch'!T$3,'System Load'!$C$4:$C$35,'System Load'!$A$4:$A$35),_xlfn.XLOOKUP($F9,'System Load'!$G$2:$J$2,'System Load'!$G$1:$J$1)))} -> 1 | U9: {=IF($F9<=5,1,INDEX('System Load'!$G$4:$J$35,_xlfn.XLOOKUP('Renewable Dispatch'!U$3,'System Load'!$C$4:$C$35,'System Load'!$A$4:$A$35),_xlfn.XLOOKUP($F9,'System Load'!$G$2:$J$2,'System Load'!$G$1:$J$1)))} -> 1 | V9: {=IF($F9<=5,1,INDEX('System Load'!$G$4:$J$35,_xlfn.XLOOKUP('Renewable Dispatch'!V$3,'System Load'!$C$4:$C$35,'System Load'!$A$4:$A$35),_xlfn.XLOOKUP($F9,'System Load'!$G$2:$J$2,'System Load'!$G$1:$J$1)))} -> 1 | W9: {=IF($F9<=5,1,INDEX('System Load'!$G$4:$J$35,_xlfn.XLOOKUP('Renewable Dispatch'!W$3,'System Load'!$C$4:$C$35,'System Load'!$A$4:$A$35),_xlfn.XLOOKUP($F9,'System Load'!$G$2:$J$2,'System Load'!$G$1:$J$1)))} -> 1
A10: Rose City Spark | B10: 2 | C10: 21 | D10: West | E10: =Portfolios!E7 -> Hydro | F10: =_xlfn.XLOOKUP(E10,'System Load'!$P$7:$P$15,'System Load'!$Q$7:$Q$15) -> 3 | G10: =Portfolios!F7 -> 145 | J10: =Bids!G9 -> 0 | K10: =Bids!I9 -> 0 | L10: =Bids!K9 -> 0 | M10: =Bids!M9 -> 0 | O10: =Bids!H9+RAND()/100 -> 0.0027816634 | P10: =Bids!J9+RAND()/100 -> 0.0013531347 | Q10: =Bids!L9+RAND()/100 -> 0.00048217992 | R10: =Bids!N9+RAND()/100 -> 0.0094034661 | T10: {=IF($F10<=5,1,INDEX('System Load'!$G$4:$J$35,_xlfn.XLOOKUP('Renewable Dispatch'!T$3,'System Load'!$C$4:$C$35,'System Load'!$A$4:$A$35),_xlfn.XLOOKUP($F10,'System Load'!$G$2:$J$2,'System Load'!$G$1:$J$1)))} -> 1 | U10: {=IF($F10<=5,1,INDEX('System Load'!$G$4:$J$35,_xlfn.XLOOKUP('Renewable Dispatch'!U$3,'System Load'!$C$4:$C$35,'System Load'!$A$4:$A$35),_xlfn.XLOOKUP($F10,'System Load'!$G$2:$J$2,'System Load'!$G$1:$J$1)))} -> 1 | V10: {=IF($F10<=5,1,INDEX('System Load'!$G$4:$J$35,_xlfn.XLOOKUP('Renewable Dispatch'!V$3,'System Load'!$C$4:$C$35,'System Load'!$A$4:$A$35),_xlfn.XLOOKUP($F10,'System Load'!$G$2:$J$2,'System Load'!$G$1:$J$1)))} -> 1 | W10: {=IF($F10<=5,1,INDEX('System Load'!$G$4:$J$35,_xlfn.XLOOKUP('Renewable Dispatch'!W$3,'System Load'!$C$4:$C$35,'System Load'!$A$4:$A$35),_xlfn.XLOOKUP($F10,'System Load'!$G$2:$J$2,'System Load'!$G$1:$J$1)))} -> 1
B11: 2 | C11: 22 | D11: West | E11: =Portfolios!E8 -> Hydro | F11: =_xlfn.XLOOKUP(E11,'System Load'!$P$7:$P$15,'System Load'!$Q$7:$Q$15) -> 3 | G11: =Portfolios!F8 -> 145 | J11: =Bids!G10 -> 0 | K11: =Bids!I10 -> 0 | L11: =Bids!K10 -> 0 | M11: =Bids!M10 -> 0 | O11: =Bids!H10+RAND()/100 -> 0.0041801122 | P11: =Bids!J10+RAND()/100 -> 0.0035956766 | Q11: =Bids!L10+RAND()/100 -> 0.0087799037 | R11: =Bids!N10+RAND()/100 -> 0.0090795363 | T11: {=IF($F11<=5,1,INDEX('System Load'!$G$4:$J$35,_xlfn.XLOOKUP('Renewable Dispatch'!T$3,'System Load'!$C$4:$C$35,'System Load'!$A$4:$A$35),_xlfn.XLOOKUP($F11,'System Load'!$G$2:$J$2,'System Load'!$G$1:$J$1)))} -> 1 | U11: {=IF($F11<=5,1,INDEX('System Load'!$G$4:$J$35,_xlfn.XLOOKUP('Renewable Dispatch'!U$3,'System Load'!$C$4:$C$35,'System Load'!$A$4:$A$35),_xlfn.XLOOKUP($F11,'System Load'!$G$2:$J$2,'System Load'!$G$1:$J$1)))} -> 1 | V11: {=IF($F11<=5,1,INDEX('System Load'!$G$4:$J$35,_xlfn.XLOOKUP('Renewable Dispatch'!V$3,'System Load'!$C$4:$C$35,'System Load'!$A$4:$A$35),_xlfn.XLOOKUP($F11,'System Load'!$G$2:$J$2,'System Load'!$G$1:$J$1)))} -> 1 | W11: {=IF($F11<=5,1,INDEX('System Load'!$G$4:$J$35,_xlfn.XLOOKUP('Renewable Dispatch'!W$3,'System Load'!$C$4:$C$35,'System Load'!$A$4:$A$35),_xlfn.XLOOKUP($F11,'System Load'!$G$2:$J$2,'System Load'!$G$1:$J$1)))} -> 1
B12: 2 | C12: 23 | D12: West | E12: =Portfolios!E9 -> Natural Gas | F12: =_xlfn.XLOOKUP(E12,'System Load'!$P$7:$P$15,'System Load'!$Q$7:$Q$15) -> 4 | G12: =Portfolios!F9 -> 750 | J12: =Bids!G11 -> 0 | K12: =Bids!I11 -> 0 | L12: =Bids!K11 -> 0 | M12: =Bids!M11 -> 0 | O12: =Bids!H11+RAND()/100 -> 0.0083019908 | P12: =Bids!J11+RAND()/100 -> 0.00028726005 | Q12: =Bids!L11+RAND()/100 -> 0.0041682408 | R12: =Bids!N11+RAND()/100 -> 0.0064821186 | T12: {=IF($F12<=5,1,INDEX('System Load'!$G$4:$J$35,_xlfn.XLOOKUP('Renewable Dispatch'!T$3,'System Load'!$C$4:$C$35,'System Load'!$A$4:$A$35),_xlfn.XLOOKUP($F12,'System Load'!$G$2:$J$2,'System Load'!$G$1:$J$1)))} -> 1 | U12: {=IF($F12<=5,1,INDEX('System Load'!$G$4:$J$35,_xlfn.XLOOKUP('Renewable Dispatch'!U$3,'System Load'!$C$4:$C$35,'System Load'!$A$4:$A$35),_xlfn.XLOOKUP($F12,'System Load'!$G$2:$J$2,'System Load'!$G$1:$J$1)))} -> 1 | V12: {=IF($F12<=5,1,INDEX('System Load'!$G$4:$J$35,_xlfn.XLOOKUP('Renewable Dispatch'!V$3,'System Load'!$C$4:$C$35,'System Load'!$A$4:$A$35),_xlfn.XLOOKUP($F12,'System Load'!$G$2:$J$2,'System Load'!$G$1:$J$1)))} -> 1 | W12: {=IF($F12<=5,1,INDEX('System Load'!$G$4:$J$35,_xlfn.XLOOKUP('Renewable Dispatch'!W$3,'System Load'!$C$4:$C$35,'System Load'!$A$4:$A$35),_xlfn.XLOOKUP($F12,'System Load'!$G$2:$J$2,'System Load'!$G$1:$J$1)))} -> 1
B13: 2 | C13: 24 | D13: West | E13: =Portfolios!E10 -> Natural Gas | F13: =_xlfn.XLOOKUP(E13,'System Load'!$P$7:$P$15,'System Load'!$Q$7:$Q$15) -> 4 | G13: =Portfolios!F10 -> 720 | J13: =Bids!G12 -> 0 | K13: =Bids!I12 -> 0 | L13: =Bids!K12 -> 0 | M13: =Bids!M12 -> 0 | O13: =Bids!H12+RAND()/100 -> 0.0098736879 | P13: =Bids!J12+RAND()/100 -> 0.00064936958 | Q13: =Bids!L12+RAND()/100 -> 0.002020279 | R13: =Bids!N12+RAND()/100 -> 0.0042503586 | T13: {=IF($F13<=5,1,INDEX('System Load'!$G$4:$J$35,_xlfn.XLOOKUP('Renewable Dispatch'!T$3,'System Load'!$C$4:$C$35,'System Load'!$A$4:$A$35),_xlfn.XLOOKUP($F13,'System Load'!$G$2:$J$2,'System Load'!$G$1:$J$1)))} -> 1 | U13: {=IF($F13<=5,1,INDEX('System Load'!$G$4:$J$35,_xlfn.XLOOKUP('Renewable Dispatch'!U$3,'System Load'!$C$4:$C$35,'System Load'!$A$4:$A$35),_xlfn.XLOOKUP($F13,'System Load'!$G$2:$J$2,'System Load'!$G$1:$J$1)))} -> 1 | V13: {=IF($F13<=5,1,INDEX('System Load'!$G$4:$J$35,_xlfn.XLOOKUP('Renewable Dispatch'!V$3,'System Load'!$C$4:$C$35,'System Load'!$A$4:$A$35),_xlfn.XLOOKUP($F13,'System Load'!$G$2:$J$2,'System Load'!$G$1:$J$1)))} -> 1 | W13: {=IF($F13<=5,1,INDEX('System Load'!$G$4:$J$35,_xlfn.XLOOKUP('Renewable Dispatch'!W$3,'System Load'!$C$4:$C$35,'System Load'!$A$4:$A$35),_xlfn.XLOOKUP($F13,'System Load'!$G$2:$J$2,'System Load'!$G$1:$J$1)))} -> 1
B14: 2 | C14: 25 | D14: West | E14: =Portfolios!E11 -> Natural Gas | F14: =_xlfn.XLOOKUP(E14,'System Load'!$P$7:$P$15,'System Load'!$Q$7:$Q$15) -> 4 | G14: =Portfolios!F11 -> 650 | J14: =Bids!G13 -> 0 | K14: =Bids!I13 -> 0 | L14: =Bids!K13 -> 0 | M14: =Bids!M13 -> 0 | O14: =Bids!H13+RAND()/100 -> 0.00041751222 | P14: =Bids!J13+RAND()/100 -> 0.0088225357 | Q14: =Bids!L13+RAND()/100 -> 0.0066054139 | R14: =Bids!N13+RAND()/100 -> 0.0041901239 | T14: {=IF($F14<=5,1,INDEX('System Load'!$G$4:$J$35,_xlfn.XLOOKUP('Renewable Dispatch'!T$3,'System Load'!$C$4:$C$35,'System Load'!$A$4:$A$35),_xlfn.XLOOKUP($F14,'System Load'!$G$2:$J$2,'System Load'!$G$1:$J$1)))} -> 1 | U14: {=IF($F14<=5,1,INDEX('System Load'!$G$4:$J$35,_xlfn.XLOOKUP('Renewable Dispatch'!U$3,'System Load'!$C$4:$C$35,'System Load'!$A$4:$A$35),_xlfn.XLOOKUP($F14,'System Load'!$G$2:$J$2,'System Load'!$G$1:$J$1)))} -> 1 | V14: {=IF($F14<=5,1,INDEX('System Load'!$G$4:$J$35,_xlfn.XLOOKUP('Renewable Dispatch'!V$3,'System Load'!$C$4:$C$35,'System Load'!$A$4:$A$35),_xlfn.XLOOKUP($F14,'System Load'!$G$2:$J$2,'System Load'!$G$1:$J$1)))} -> 1 | W14: {=IF($F14<=5,1,INDEX('System Load'!$G$4:$J$35,_xlfn.XLOOKUP('Renewable Dispatch'!W$3,'System Load'!$C$4:$C$35,'System Load'!$A$4:$A$35),_xlfn.XLOOKUP($F14,'System Load'!$G$2:$J$2,'System Load'!$G$1:$J$1)))} -> 1
B15: 2 | C15: 26 | D15: West | E15: =Portfolios!E12 -> Natural Gas | F15: =_xlfn.XLOOKUP(E15,'System Load'!$P$7:$P$15,'System Load'!$Q$7:$Q$15) -> 4 | G15: =Portfolios!F12 -> 600 | J15: =Bids!G14 -> 0 | K15: =Bids!I14 -> 0 | L15: =Bids!K14 -> 0 | M15: =Bids!M14 -> 0 | O15: =Bids!H14+RAND()/100 -> 0.0019378093 | P15: =Bids!J14+RAND()/100 -> 0.0036290407 | Q15: =Bids!L14+RAND()/100 -> 0.0042234295 | R15: =Bids!N14+RAND()/100 -> 0.0082908651 | T15: {=IF($F15<=5,1,INDEX('System Load'!$G$4:$J$35,_xlfn.XLOOKUP('Renewable Dispatch'!T$3,'System Load'!$C$4:$C$35,'System Load'!$A$4:$A$35),_xlfn.XLOOKUP($F15,'System Load'!$G$2:$J$2,'System Load'!$G$1:$J$1)))} -> 1 | U15: {=IF($F15<=5,1,INDEX('System Load'!$G$4:$J$35,_xlfn.XLOOKUP('Renewable Dispatch'!U$3,'System Load'!$C$4:$C$35,'System Load'!$A$4:$A$35),_xlfn.XLOOKUP($F15,'System Load'!$G$2:$J$2,'System Load'!$G$1:$J$1)))} -> 1 | V15: {=IF($F15<=5,1,INDEX('System Load'!$G$4:$J$35,_xlfn.XLOOKUP('Renewable Dispatch'!V$3,'System Load'!$C$4:$C$35,'System Load'!$A$4:$A$35),_xlfn.XLOOKUP($F15,'System Load'!$G$2:$J$2,'System Load'!$G$1:$J$1)))} -> 1 | W15: {=IF($F15<=5,1,INDEX('System Load'!$G$4:$J$35,_xlfn.XLOOKUP('Renewable Dispatch'!W$3,'System Load'!$C$4:$C$35,'System Load'!$A$4:$A$35),_xlfn.XLOOKUP($F15,'System Load'!$G$2:$J$2,'System Load'!$G$1:$J$1)))} -> 1
B16: 2 | C16: 27 | D16: West | E16: =Portfolios!E13 -> Solar | F16: =_xlfn.XLOOKUP(E16,'System Load'!$P$7:$P$15,'System Load'!$Q$7:$Q$15) -> 8 | G16: =Portfolios!F13 -> 540 | J16: =Bids!G15 -> 0 | K16: =Bids!I15 -> 0 | L16: =Bids!K15 -> 0 | M16: =Bids!M15 -> 0 | O16: =Bids!H15+RAND()/100 -> 0.0026325171 | P16: =Bids!J15+RAND()/100 -> 0.0042165595 | Q16: =Bids!L15+RAND()/100 -> 0.0087247247 | R16: =Bids!N15+RAND()/100 -> 0.0056362974 | T16: {=IF($F16<=5,1,INDEX('System Load'!$G$4:$J$35,_xlfn.XLOOKUP('Renewable Dispatch'!T$3,'System Load'!$C$4:$C$35,'System Load'!$A$4:$A$35),_xlfn.XLOOKUP($F16,'System Load'!$G$2:$J$2,'System Load'!$G$1:$J$1)))} -> 0.44438288 | U16: {=IF($F16<=5,1,INDEX('System Load'!$G$4:$J$35,_xlfn.XLOOKUP('Renewable Dispatch'!U$3,'System Load'!$C$4:$C$35,'System Load'!$A$4:$A$35),_xlfn.XLOOKUP($F16,'System Load'!$G$2:$J$2,'System Load'!$G$1:$J$1)))} -> 1 | V16: {=IF($F16<=5,1,INDEX('System Load'!$G$4:$J$35,_xlfn.XLOOKUP('Renewable Dispatch'!V$3,'System Load'!$C$4:$C$35,'System Load'!$A$4:$A$35),_xlfn.XLOOKUP($F16,'System Load'!$G$2:$J$2,'System Load'!$G$1:$J$1)))} -> 0.79116936 | W16: {=IF($F16<=5,1,INDEX('System Load'!$G$4:$J$35,_xlfn.XLOOKUP('Renewable Dispatch'!W$3,'System Load'!$C$4:$C$35,'System Load'!$A$4:$A$35),_xlfn.XLOOKUP($F16,'System Load'!$G$2:$J$2,'System Load'!$G$1:$J$1)))} -> 0.23501107
A17: Cascadia Generation | B17: 3 | C17: 31 | D17: West | E17: =Portfolios!E14 -> Natural Gas | F17: =_xlfn.XLOOKUP(E17,'System Load'!$P$7:$P$15,'System Load'!$Q$7:$Q$15) -> 4 | G17: =Portfolios!F14 -> 400 | J17: =Bids!G16 -> 0 | K17: =Bids!I16 -> 0 | L17: =Bids!K16 -> 0 | M17: =Bids!M16 -> 0 | O17: =Bids!H16+RAND()/100 -> 0.0016160226 | P17: =Bids!J16+RAND()/100 -> 0.0025673168 | Q17: =Bids!L16+RAND()/100 -> 0.00113666 | R17: =Bids!N16+RAND()/100 -> 0.0071888371 | T17: {=IF($F17<=5,1,INDEX('System Load'!$G$4:$J$35,_xlfn.XLOOKUP('Renewable Dispatch'!T$3,'System Load'!$C$4:$C$35,'System Load'!$A$4:$A$35),_xlfn.XLOOKUP($F17,'System Load'!$G$2:$J$2,'System Load'!$G$1:$J$1)))} -> 1 | U17: {=IF($F17<=5,1,INDEX('System Load'!$G$4:$J$35,_xlfn.XLOOKUP('Renewable Dispatch'!U$3,'System Load'!$C$4:$C$35,'System Load'!$A$4:$A$35),_xlfn.XLOOKUP($F17,'System Load'!$G$2:$J$2,'System Load'!$G$1:$J$1)))} -> 1 | V17: {=IF($F17<=5,1,INDEX('System Load'!$G$4:$J$35,_xlfn.XLOOKUP('Renewable Dispatch'!V$3,'System Load'!$C$4:$C$35,'System Load'!$A$4:$A$35),_xlfn.XLOOKUP($F17,'System Load'!$G$2:$J$2,'System Load'!$G$1:$J$1)))} -> 1 | W17: {=IF($F17<=5,1,INDEX('System Load'!$G$4:$J$35,_xlfn.XLOOKUP('Renewable Dispatch'!W$3,'System Load'!$C$4:$C$35,'System Load'!$A$4:$A$35),_xlfn.XLOOKUP($F17,'System Load'!$G$2:$J$2,'System Load'!$G$1:$J$1)))} -> 1
B18: 3 | C18: 32 | D18: West | E18: =Portfolios!E15 -> Solar | F18: =_xlfn.XLOOKUP(E18,'System Load'!$P$7:$P$15,'System Load'!$Q$7:$Q$15) -> 8 | G18: =Portfolios!F15 -> 600 | J18: =Bids!G17 -> 0 | K18: =Bids!I17 -> 0 | L18: =Bids!K17 -> 0 | M18: =Bids!M17 -> 0 | O18: =Bids!H17+RAND()/100 -> 0.0090859818 | P18: =Bids!J17+RAND()/100 -> 0.0033451307 | Q18: =Bids!L17+RAND()/100 -> 0.0036126121 | R18: =Bids!N17+RAND()/100 -> 0.0074622154 | T18: {=IF($F18<=5,1,INDEX('System Load'!$G$4:$J$35,_xlfn.XLOOKUP('Renewable Dispatch'!T$3,'System Load'!$C$4:$C$35,'System Load'!$A$4:$A$35),_xlfn.XLOOKUP($F18,'System Load'!$G$2:$J$2,'System Load'!$G$1:$J$1)))} -> 0.44438288 | U18: {=IF($F18<=5,1,INDEX('System Load'!$G$4:$J$35,_xlfn.XLOOKUP('Renewable Dispatch'!U$3,'System Load'!$C$4:$C$35,'System Load'!$A$4:$A$35),_xlfn.XLOOKUP($F18,'System Load'!$G$2:$J$2,'System Load'!$G$1:$J$1)))} -> 1 | V18: {=IF($F18<=5,1,INDEX('System Load'!$G$4:$J$35,_xlfn.XLOOKUP('Renewable Dispatch'!V$3,'System Load'!$C$4:$C$35,'System Load'!$A$4:$A$35),_xlfn.XLOOKUP($F18,'System Load'!$G$2:$J$2,'System Load'!$G$1:$J$1)))} -> 0.79116936 | W18: {=IF($F18<=5,1,INDEX('System Load'!$G$4:$J$35,_xlfn.XLOOKUP('Renewable Dispatch'!W$3,'System Load'!$C$4:$C$35,'System Load'!$A$4:$A$35),_xlfn.XLOOKUP($F18,'System Load'!$G$2:$J$2,'System Load'!$G$1:$J$1)))} -> 0.23501107
B19: 3 | C19: 33 | D19: West | E19: =Portfolios!E16 -> Solar | F19: =_xlfn.XLOOKUP(E19,'System Load'!$P$7:$P$15,'System Load'!$Q$7:$Q$15) -> 8 | G19: =Portfolios!F16 -> 600 | J19: =Bids!G18 -> 0 | K19: =Bids!I18 -> 0 | L19: =Bids!K18 -> 0 | M19: =Bids!M18 -> 0 | O19: =Bids!H18+RAND()/100 -> 0.00012799897 | P19: =Bids!J18+RAND()/100 -> 0.0081212533 | Q19: =Bids!L18+RAND()/100 -> 0.00032959649 | R19: =Bids!N18+RAND()/100 -> 0.0099541728 | T19: {=IF($F19<=5,1,INDEX('System Load'!$G$4:$J$35,_xlfn.XLOOKUP('Renewable Dispatch'!T$3,'System Load'!$C$4:$C$35,'System Load'!$A$4:$A$35),_xlfn.XLOOKUP($F19,'System Load'!$G$2:$J$2,'System Load'!$G$1:$J$1)))} -> 0.44438288 | U19: {=IF($F19<=5,1,INDEX('System Load'!$G$4:$J$35,_xlfn.XLOOKUP('Renewable Dispatch'!U$3,'System Load'!$C$4:$C$35,'System Load'!$A$4:$A$35),_xlfn.XLOOKUP($F19,'System Load'!$G$2:$J$2,'System Load'!$G$1:$J$1)))} -> 1 | V19: {=IF($F19<=5,1,INDEX('System Load'!$G$4:$J$35,_xlfn.XLOOKUP('Renewable Dispatch'!V$3,'System Load'!$C$4:$C$35,'System Load'!$A$4:$A$35),_xlfn.XLOOKUP($F19,'System Load'!$G$2:$J$2,'System Load'!$G$1:$J$1)))} -> 0.79116936 | W19: {=IF($F19<=5,1,INDEX('System Load'!$G$4:$J$35,_xlfn.XLOOKUP('Renewable Dispatch'!W$3,'System Load'!$C$4:$C$35,'System Load'!$A$4:$A$35),_xlfn.XLOOKUP($F19,'System Load'!$G$2:$J$2,'System Load'!$G$1:$J$1)))} -> 0.23501107
B20: 3 | C20: 34 | D20: West | E20: =Portfolios!E17 -> Solar | F20: =_xlfn.XLOOKUP(E20,'System Load'!$P$7:$P$15,'System Load'!$Q$7:$Q$15) -> 8 | G20: =Portfolios!F17 -> 475 | J20: =Bids!G19 -> 0 | K20: =Bids!I19 -> 0 | L20: =Bids!K19 -> 0 | M20: =Bids!M19 -> 0 | O20: =Bids!H19+RAND()/100 -> 0.0066081567 | P20: =Bids!J19+RAND()/100 -> 0.0042557414 | Q20: =Bids!L19+RAND()/100 -> 0.0014077622 | R20: =Bids!N19+RAND()/100 -> 0.00034579624 | T20: {=IF($F20<=5,1,INDEX('System Load'!$G$4:$J$35,_xlfn.XLOOKUP('Renewable Dispatch'!T$3,'System Load'!$C$4:$C$35,'System Load'!$A$4:$A$35),_xlfn.XLOOKUP($F20,'System Load'!$G$2:$J$2,'System Load'!$G$1:$J$1)))} -> 0.44438288 | U20: {=IF($F20<=5,1,INDEX('System Load'!$G$4:$J$35,_xlfn.XLOOKUP('Renewable Dispatch'!U$3,'System Load'!$C$4:$C$35,'System Load'!$A$4:$A$35),_xlfn.XLOOKUP($F20,'System Load'!$G$2:$J$2,'System Load'!$G$1:$J$1)))} -> 1 | V20: {=IF($F20<=5,1,INDEX('System Load'!$G$4:$J$35,_xlfn.XLOOKUP('Renewable Dispatch'!V$3,'System Load'!$C$4:$C$35,'System Load'!$A$4:$A$35),_xlfn.XLOOKUP($F20,'System Load'!$G$2:$J$2,'System Load'!$G$1:$J$1)))} -> 0.79116936 | W20: {=IF($F20<=5,1,INDEX('System Load'!$G$4:$J$35,_xlfn.XLOOKUP('Renewable Dispatch'!W$3,'System Load'!$C$4:$C$35,'System Load'!$A$4:$A$35),_xlfn.XLOOKUP($F20,'System Load'!$G$2:$J$2,'System Load'!$G$1:$J$1)))} -> 0.23501107
B21: 3 | C21: 35 | D21: West | E21: =Portfolios!E18 -> Solar | F21: =_xlfn.XLOOKUP(E21,'System Load'!$P$7:$P$15,'System Load'!$Q$7:$Q$15) -> 8 | G21: =Portfolios!F18 -> 350 | J21: =Bids!G20 -> 0 | K21: =Bids!I20 -> 0 | L21: =Bids!K20 -> 0 | M21: =Bids!M20 -> 0 | O21: =Bids!H20+RAND()/100 -> 0.0072824299 | P21: =Bids!J20+RAND()/100 -> 0.0070115683 | Q21: =Bids!L20+RAND()/100 -> 0.0085586346 | R21: =Bids!N20+RAND()/100 -> 0.0098252099 | T21: {=IF($F21<=5,1,INDEX('System Load'!$G$4:$J$35,_xlfn.XLOOKUP('Renewable Dispatch'!T$3,'System Load'!$C$4:$C$35,'System Load'!$A$4:$A$35),_xlfn.XLOOKUP($F21,'System Load'!$G$2:$J$2,'System Load'!$G$1:$J$1)))} -> 0.44438288 | U21: {=IF($F21<=5,1,INDEX('System Load'!$G$4:$J$35,_xlfn.XLOOKUP('Renewable Dispatch'!U$3,'System Load'!$C$4:$C$35,'System Load'!$A$4:$A$35),_xlfn.XLOOKUP($F21,'System Load'!$G$2:$J$2,'System Load'!$G$1:$J$1)))} -> 1 | V21: {=IF($F21<=5,1,INDEX('System Load'!$G$4:$J$35,_xlfn.XLOOKUP('Renewable Dispatch'!V$3,'System Load'!$C$4:$C$35,'System Load'!$A$4:$A$35),_xlfn.XLOOKUP($F21,'System Load'!$G$2:$J$2,'System Load'!$G$1:$J$1)))} -> 0.79116936 | W21: {=IF($F21<=5,1,INDEX('System Load'!$G$4:$J$35,_xlfn.XLOOKUP('Renewable Dispatch'!W$3,'System Load'!$C$4:$C$35,'System Load'!$A$4:$A$35),_xlfn.XLOOKUP($F21,'System Load'!$G$2:$J$2,'System Load'!$G$1:$J$1)))} -> 0.23501107
B22: 3 | C22: 36 | D22: West | E22: =Portfolios!E19 -> Onshore Wind | F22: =_xlfn.XLOOKUP(E22,'System Load'!$P$7:$P$15,'System Load'!$Q$7:$Q$15) -> 7 | G22: =Portfolios!F19 -> 375 | J22: =Bids!G21 -> 0 | K22: =Bids!I21 -> 0 | L22: =Bids!K21 -> 0 | M22: =Bids!M21 -> 0 | O22: =Bids!H21+RAND()/100 -> 0.0081872165 | P22: =Bids!J21+RAND()/100 -> 0.0082834051 | Q22: =Bids!L21+RAND()/100 -> 0.0038430214 | R22: =Bids!N21+RAND()/100 -> 0.00026664544 | T22: {=IF($F22<=5,1,INDEX('System Load'!$G$4:$J$35,_xlfn.XLOOKUP('Renewable Dispatch'!T$3,'System Load'!$C$4:$C$35,'System Load'!$A$4:$A$35),_xlfn.XLOOKUP($F22,'System Load'!$G$2:$J$2,'System Load'!$G$1:$J$1)))} -> 0.055797368 | U22: {=IF($F22<=5,1,INDEX('System Load'!$G$4:$J$35,_xlfn.XLOOKUP('Renewable Dispatch'!U$3,'System Load'!$C$4:$C$35,'System Load'!$A$4:$A$35),_xlfn.XLOOKUP($F22,'System Load'!$G$2:$J$2,'System Load'!$G$1:$J$1)))} -> 0.70863205 | V22: {=IF($F22<=5,1,INDEX('System Load'!$G$4:$J$35,_xlfn.XLOOKUP('Renewable Dispatch'!V$3,'System Load'!$C$4:$C$35,'System Load'!$A$4:$A$35),_xlfn.XLOOKUP($F22,'System Load'!$G$2:$J$2,'System Load'!$G$1:$J$1)))} -> 0.4494775 | W22: {=IF($F22<=5,1,INDEX('System Load'!$G$4:$J$35,_xlfn.XLOOKUP('Renewable Dispatch'!W$3,'System Load'!$C$4:$C$35,'System Load'!$A$4:$A$35),_xlfn.XLOOKUP($F22,'System Load'!$G$2:$J$2,'System Load'!$G$1:$J$1)))} -> 0.11977743
B23: 3 | C23: 37 | D23: West | E23: =Portfolios!E20 -> Onshore Wind | F23: =_xlfn.XLOOKUP(E23,'System Load'!$P$7:$P$15,'System Load'!$Q$7:$Q$15) -> 7 | G23: =Portfolios!F20 -> 375 | J23: =Bids!G22 -> 0 | K23: =Bids!I22 -> 0 | L23: =Bids!K22 -> 0 | M23: =Bids!M22 -> 0 | O23: =Bids!H22+RAND()/100 -> 0.0080914403 | P23: =Bids!J22+RAND()/100 -> 0.0012123671 | Q23: =Bids!L22+RAND()/100 -> 0.009170544 | R23: =Bids!N22+RAND()/100 -> 0.0028103894 | T23: {=IF($F23<=5,1,INDEX('System Load'!$G$4:$J$35,_xlfn.XLOOKUP('Renewable Dispatch'!T$3,'System Load'!$C$4:$C$35,'System Load'!$A$4:$A$35),_xlfn.XLOOKUP($F23,'System Load'!$G$2:$J$2,'System Load'!$G$1:$J$1)))} -> 0.055797368 | U23: {=IF($F23<=5,1,INDEX('System Load'!$G$4:$J$35,_xlfn.XLOOKUP('Renewable Dispatch'!U$3,'System Load'!$C$4:$C$35,'System Load'!$A$4:$A$35),_xlfn.XLOOKUP($F23,'System Load'!$G$2:$J$2,'System Load'!$G$1:$J$1)))} -> 0.70863205 | V23: {=IF($F23<=5,1,INDEX('System Load'!$G$4:$J$35,_xlfn.XLOOKUP('Renewable Dispatch'!V$3,'System Load'!$C$4:$C$35,'System Load'!$A$4:$A$35),_xlfn.XLOOKUP($F23,'System Load'!$G$2:$J$2,'System Load'!$G$1:$J$1)))} -> 0.4494775 | W23: {=IF($F23<=5,1,INDEX('System Load'!$G$4:$J$35,_xlfn.XLOOKUP('Renewable Dispatch'!W$3,'System Load'!$C$4:$C$35,'System Load'!$A$4:$A$35),_xlfn.XLOOKUP($F23,'System Load'!$G$2:$J$2,'System Load'!$G$1:$J$1)))} -> 0.11977743
B24: 3 | C24: 38 | D24: West | E24: =Portfolios!E21 -> Onshore Wind | F24: =_xlfn.XLOOKUP(E24,'System Load'!$P$7:$P$15,'System Load'!$Q$7:$Q$15) -> 7 | G24: =Portfolios!F21 -> 375 | J24: =Bids!G23 -> 0 | K24: =Bids!I23 -> 0 | L24: =Bids!K23 -> 0 | M24: =Bids!M23 -> 0 | O24: =Bids!H23+RAND()/100 -> 0.0083865012 | P24: =Bids!J23+RAND()/100 -> 0.0089788524 | Q24: =Bids!L23+RAND()/100 -> 0.0094284665 | R24: =Bids!N23+RAND()/100 -> 0.0053937892 | T24: {=IF($F24<=5,1,INDEX('System Load'!$G$4:$J$35,_xlfn.XLOOKUP('Renewable Dispatch'!T$3,'System Load'!$C$4:$C$35,'System Load'!$A$4:$A$35),_xlfn.XLOOKUP($F24,'System Load'!$G$2:$J$2,'System Load'!$G$1:$J$1)))} -> 0.055797368 | U24: {=IF($F24<=5,1,INDEX('System Load'!$G$4:$J$35,_xlfn.XLOOKUP('Renewable Dispatch'!U$3,'System Load'!$C$4:$C$35,'System Load'!$A$4:$A$35),_xlfn.XLOOKUP($F24,'System Load'!$G$2:$J$2,'System Load'!$G$1:$J$1)))} -> 0.70863205 | V24: {=IF($F24<=5,1,INDEX('System Load'!$G$4:$J$35,_xlfn.XLOOKUP('Renewable Dispatch'!V$3,'System Load'!$C$4:$C$35,'System Load'!$A$4:$A$35),_xlfn.XLOOKUP($F24,'System Load'!$G$2:$J$2,'System Load'!$G$1:$J$1)))} -> 0.4494775 | W24: {=IF($F24<=5,1,INDEX('System Load'!$G$4:$J$35,_xlfn.XLOOKUP('Renewable Dispatch'!W$3,'System Load'!$C$4:$C$35,'System Load'!$A$4:$A$35),_xlfn.XLOOKUP($F24,'System Load'!$G$2:$J$2,'System Load'!$G$1:$J$1)))} -> 0.11977743
A25: San Juan Power & Light | B25: 4 | C25: 41 | D25: West | E25: =Portfolios!E22 -> Offshore Wind | F25: =_xlfn.XLOOKUP(E25,'System Load'!$P$7:$P$15,'System Load'!$Q$7:$Q$15) -> 6 | G25: =Portfolios!F22 -> 820 | J25: =Bids!G24 -> 0 | K25: =Bids!I24 -> 0 | L25: =Bids!K24 -> 0 | M25: =Bids!M24 -> 0 | O25: =Bids!H24+RAND()/100 -> 0.0048387742 | P25: =Bids!J24+RAND()/100 -> 0.0059272364 | Q25: =Bids!L24+RAND()/100 -> 0.0073784505 | R25: =Bids!N24+RAND()/100 -> 0.0068504976 | T25: {=IF($F25<=5,1,INDEX('System Load'!$G$4:$J$35,_xlfn.XLOOKUP('Renewable Dispatch'!T$3,'System Load'!$C$4:$C$35,'System Load'!$A$4:$A$35),_xlfn.XLOOKUP($F25,'System Load'!$G$2:$J$2,'System Load'!$G$1:$J$1)))} -> 0.54509912 | U25: {=IF($F25<=5,1,INDEX('System Load'!$G$4:$J$35,_xlfn.XLOOKUP('Renewable Dispatch'!U$3,'System Load'!$C$4:$C$35,'System Load'!$A$4:$A$35),_xlfn.XLOOKUP($F25,'System Load'!$G$2:$J$2,'System Load'!$G$1:$J$1)))} -> 1 | V25: {=IF($F25<=5,1,INDEX('System Load'!$G$4:$J$35,_xlfn.XLOOKUP('Renewable Dispatch'!V$3,'System Load'!$C$4:$C$35,'System Load'!$A$4:$A$35),_xlfn.XLOOKUP($F25,'System Load'!$G$2:$J$2,'System Load'!$G$1:$J$1)))} -> 0.59113402 | W25: {=IF($F25<=5,1,INDEX('System Load'!$G$4:$J$35,_xlfn.XLOOKUP('Renewable Dispatch'!W$3,'System Load'!$C$4:$C$35,'System Load'!$A$4:$A$35),_xlfn.XLOOKUP($F25,'System Load'!$G$2:$J$2,'System Load'!$G$1:$J$1)))} -> 0.21486811
B26: 4 | C26: 42 | D26: West | E26: =Portfolios!E23 -> Offshore Wind | F26: =_xlfn.XLOOKUP(E26,'System Load'!$P$7:$P$15,'System Load'!$Q$7:$Q$15) -> 6 | G26: =Portfolios!F23 -> 780 | J26: =Bids!G25 -> 0 | K26: =Bids!I25 -> 0 | L26: =Bids!K25 -> 0 | M26: =Bids!M25 -> 0 | O26: =Bids!H25+RAND()/100 -> 0.0031092222 | P26: =Bids!J25+RAND()/100 -> 0.0025007271 | Q26: =Bids!L25+RAND()/100 -> 0.0052312028 | R26: =Bids!N25+RAND()/100 -> 0.0095112068 | T26: {=IF($F26<=5,1,INDEX('System Load'!$G$4:$J$35,_xlfn.XLOOKUP('Renewable Dispatch'!T$3,'System Load'!$C$4:$C$35,'System Load'!$A$4:$A$35),_xlfn.XLOOKUP($F26,'System Load'!$G$2:$J$2,'System Load'!$G$1:$J$1)))} -> 0.54509912 | U26: {=IF($F26<=5,1,INDEX('System Load'!$G$4:$J$35,_xlfn.XLOOKUP('Renewable Dispatch'!U$3,'System Load'!$C$4:$C$35,'System Load'!$A$4:$A$35),_xlfn.XLOOKUP($F26,'System Load'!$G$2:$J$2,'System Load'!$G$1:$J$1)))} -> 1 | V26: {=IF($F26<=5,1,INDEX('System Load'!$G$4:$J$35,_xlfn.XLOOKUP('Renewable Dispatch'!V$3,'System Load'!$C$4:$C$35,'System Load'!$A$4:$A$35),_xlfn.XLOOKUP($F26,'System Load'!$G$2:$J$2,'System Load'!$G$1:$J$1)))} -> 0.59113402 | W26: {=IF($F26<=5,1,INDEX('System Load'!$G$4:$J$35,_xlfn.XLOOKUP('Renewable Dispatch'!W$3,'System Load'!$C$4:$C$35,'System Load'!$A$4:$A$35),_xlfn.XLOOKUP($F26,'System Load'!$G$2:$J$2,'System Load'!$G$1:$J$1)))} -> 0.21486811
B27: 4 | C27: 43 | D27: West | E27: =Portfolios!E24 -> Offshore Wind | F27: =_xlfn.XLOOKUP(E27,'System Load'!$P$7:$P$15,'System Load'!$Q$7:$Q$15) -> 6 | G27: =Portfolios!F24 -> 700 | J27: =Bids!G26 -> 0 | K27: =Bids!I26 -> 0 | L27: =Bids!K26 -> 0 | M27: =Bids!M26 -> 0 | O27: =Bids!H26+RAND()/100 -> 0.00055305486 | P27: =Bids!J26+RAND()/100 -> 0.0062332454 | Q27: =Bids!L26+RAND()/100 -> 0.005730311 | R27: =Bids!N26+RAND()/100 -> 0.0033931995 | T27: {=IF($F27<=5,1,INDEX('System Load'!$G$4:$J$35,_xlfn.XLOOKUP('Renewable Dispatch'!T$3,'System Load'!$C$4:$C$35,'System Load'!$A$4:$A$35),_xlfn.XLOOKUP($F27,'System Load'!$G$2:$J$2,'System Load'!$G$1:$J$1)))} -> 0.54509912 | U27: {=IF($F27<=5,1,INDEX('System Load'!$G$4:$J$35,_xlfn.XLOOKUP('Renewable Dispatch'!U$3,'System Load'!$C$4:$C$35,'System Load'!$A$4:$A$35),_xlfn.XLOOKUP($F27,'System Load'!$G$2:$J$2,'System Load'!$G$1:$J$1)))} -> 1 | V27: {=IF($F27<=5,1,INDEX('System Load'!$G$4:$J$35,_xlfn.XLOOKUP('Renewable Dispatch'!V$3,'System Load'!$C$4:$C$35,'System Load'!$A$4:$A$35),_xlfn.XLOOKUP($F27,'System Load'!$G$2:$J$2,'System Load'!$G$1:$J$1)))} -> 0.59113402 | W27: {=IF($F27<=5,1,INDEX('System Load'!$G$4:$J$35,_xlfn.XLOOKUP('Renewable Dispatch'!W$3,'System Load'!$C$4:$C$35,'System Load'!$A$4:$A$35),_xlfn.XLOOKUP($F27,'System Load'!$G$2:$J$2,'System Load'!$G$1:$J$1)))} -> 0.21486811
B28: 4 | C28: 44 | D28: West | E28: =Portfolios!E25 -> Wave | F28: =_xlfn.XLOOKUP(E28,'System Load'!$P$7:$P$15,'System Load'!$Q$7:$Q$15) -> 9 | G28: =Portfolios!F25 -> 425 | J28: =Bids!G27 -> 0 | K28: =Bids!I27 -> 0 | L28: =Bids!K27 -> 0 | M28: =Bids!M27 -> 0 | O28: =Bids!H27+RAND()/100 -> 0.0074459748 | P28: =Bids!J27+RAND()/100 -> 0.0075722624 | Q28: =Bids!L27+RAND()/100 -> 0.0088635257 | R28: =Bids!N27+RAND()/100 -> 0.0026513187 | T28: {=IF($F28<=5,1,INDEX('System Load'!$G$4:$J$35,_xlfn.XLOOKUP('Renewable Dispatch'!T$3,'System Load'!$C$4:$C$35,'System Load'!$A$4:$A$35),_xlfn.XLOOKUP($F28,'System Load'!$G$2:$J$2,'System Load'!$G$1:$J$1)))} -> 0.87775556 | U28: {=IF($F28<=5,1,INDEX('System Load'!$G$4:$J$35,_xlfn.XLOOKUP('Renewable Dispatch'!U$3,'System Load'!$C$4:$C$35,'System Load'!$A$4:$A$35),_xlfn.XLOOKUP($F28,'System Load'!$G$2:$J$2,'System Load'!$G$1:$J$1)))} -> 0.91193024 | V28: {=IF($F28<=5,1,INDEX('System Load'!$G$4:$J$35,_xlfn.XLOOKUP('Renewable Dispatch'!V$3,'System Load'!$C$4:$C$35,'System Load'!$A$4:$A$35),_xlfn.XLOOKUP($F28,'System Load'!$G$2:$J$2,'System Load'!$G$1:$J$1)))} -> 0.86509151 | W28: {=IF($F28<=5,1,INDEX('System Load'!$G$4:$J$35,_xlfn.XLOOKUP('Renewable Dispatch'!W$3,'System Load'!$C$4:$C$35,'System Load'!$A$4:$A$35),_xlfn.XLOOKUP($F28,'System Load'!$G$2:$J$2,'System Load'!$G$1:$J$1)))} -> 0.92793646
B29: 4 | C29: 45 | D29: West | E29: =Portfolios!E26 -> Wave | F29: =_xlfn.XLOOKUP(E29,'System Load'!$P$7:$P$15,'System Load'!$Q$7:$Q$15) -> 9 | G29: =Portfolios!F26 -> 425 | J29: =Bids!G28 -> 0 | K29: =Bids!I28 -> 0 | L29: =Bids!K28 -> 0 | M29: =Bids!M28 -> 0 | O29: =Bids!H28+RAND()/100 -> 0.0031234104 | P29: =Bids!J28+RAND()/100 -> 0.0084183429 | Q29: =Bids!L28+RAND()/100 -> 0.0021519777 | R29: =Bids!N28+RAND()/100 -> 0.0033656778 | T29: {=IF($F29<=5,1,INDEX('System Load'!$G$4:$J$35,_xlfn.XLOOKUP('Renewable Dispatch'!T$3,'System Load'!$C$4:$C$35,'System Load'!$A$4:$A$35),_xlfn.XLOOKUP($F29,'System Load'!$G$2:$J$2,'System Load'!$G$1:$J$1)))} -> 0.87775556 | U29: {=IF($F29<=5,1,INDEX('System Load'!$G$4:$J$35,_xlfn.XLOOKUP('Renewable Dispatch'!U$3,'System Load'!$C$4:$C$35,'System Load'!$A$4:$A$35),_xlfn.XLOOKUP($F29,'System Load'!$G$2:$J$2,'System Load'!$G$1:$J$1)))} -> 0.91193024 | V29: {=IF($F29<=5,1,INDEX('System Load'!$G$4:$J$35,_xlfn.XLOOKUP('Renewable Dispatch'!V$3,'System Load'!$C$4:$C$35,'System Load'!$A$4:$A$35),_xlfn.XLOOKUP($F29,'System Load'!$G$2:$J$2,'System Load'!$G$1:$J$1)))} -> 0.86509151 | W29: {=IF($F29<=5,1,INDEX('System Load'!$G$4:$J$35,_xlfn.XLOOKUP('Renewable Dispatch'!W$3,'System Load'!$C$4:$C$35,'System Load'!$A$4:$A$35),_xlfn.XLOOKUP($F29,'System Load'!$G$2:$J$2,'System Load'!$G$1:$J$1)))} -> 0.92793646
B30: 4 | C30: 46 | D30: West | E30: =Portfolios!E27 -> Natural Gas | F30: =_xlfn.XLOOKUP(E30,'System Load'!$P$7:$P$15,'System Load'!$Q$7:$Q$15) -> 4 | G30: =Portfolios!F27 -> 225 | J30: =Bids!G29 -> 0 | K30: =Bids!I29 -> 0 | L30: =Bids!K29 -> 0 | M30: =Bids!M29 -> 0 | O30: =Bids!H29+RAND()/100 -> 0.0090642599 | P30: =Bids!J29+RAND()/100 -> 0.0040409102 | Q30: =Bids!L29+RAND()/100 -> 0.0017075155 | R30: =Bids!N29+RAND()/100 -> 0.0056709565 | T30: {=IF($F30<=5,1,INDEX('System Load'!$G$4:$J$35,_xlfn.XLOOKUP('Renewable Dispatch'!T$3,'System Load'!$C$4:$C$35,'System Load'!$A$4:$A$35),_xlfn.XLOOKUP($F30,'System Load'!$G$2:$J$2,'System Load'!$G$1:$J$1)))} -> 1 | U30: {=IF($F30<=5,1,INDEX('System Load'!$G$4:$J$35,_xlfn.XLOOKUP('Renewable Dispatch'!U$3,'System Load'!$C$4:$C$35,'System Load'!$A$4:$A$35),_xlfn.XLOOKUP($F30,'System Load'!$G$2:$J$2,'System Load'!$G$1:$J$1)))} -> 1 | V30: {=IF($F30<=5,1,INDEX('System Load'!$G$4:$J$35,_xlfn.XLOOKUP('Renewable Dispatch'!V$3,'System Load'!$C$4:$C$35,'System Load'!$A$4:$A$35),_xlfn.XLOOKUP($F30,'System Load'!$G$2:$J$2,'System Load'!$G$1:$J$1)))} -> 1 | W30: {=IF($F30<=5,1,INDEX('System Load'!$G$4:$J$35,_xlfn.XLOOKUP('Renewable Dispatch'!W$3,'System Load'!$C$4:$C$35,'System Load'!$A$4:$A$35),_xlfn.XLOOKUP($F30,'System Load'!$G$2:$J$2,'System Load'!$G$1:$J$1)))} -> 1
B31: 4 | C31: 47 | D31: West | E31: =Portfolios!E28 -> Natural Gas | F31: =_xlfn.XLOOKUP(E31,'System Load'!$P$7:$P$15,'System Load'!$Q$7:$Q$15) -> 4 | G31: =Portfolios!F28 -> 175 | J31: =Bids!G30 -> 0 | K31: =Bids!I30 -> 0 | L31: =Bids!K30 -> 0 | M31: =Bids!M30 -> 0 | O31: =Bids!H30+RAND()/100 -> 0.0096245619 | P31: =Bids!J30+RAND()/100 -> 0.0037753919 | Q31: =Bids!L30+RAND()/100 -> 0.0096277425 | R31: =Bids!N30+RAND()/100 -> 0.0074005477 | T31: {=IF($F31<=5,1,INDEX('System Load'!$G$4:$J$35,_xlfn.XLOOKUP('Renewable Dispatch'!T$3,'System Load'!$C$4:$C$35,'System Load'!$A$4:$A$35),_xlfn.XLOOKUP($F31,'System Load'!$G$2:$J$2,'System Load'!$G$1:$J$1)))} -> 1 | U31: {=IF($F31<=5,1,INDEX('System Load'!$G$4:$J$35,_xlfn.XLOOKUP('Renewable Dispatch'!U$3,'System Load'!$C$4:$C$35,'System Load'!$A$4:$A$35),_xlfn.XLOOKUP($F31,'System Load'!$G$2:$J$2,'System Load'!$G$1:$J$1)))} -> 1 | V31: {=IF($F31<=5,1,INDEX('System Load'!$G$4:$J$35,_xlfn.XLOOKUP('Renewable Dispatch'!V$3,'System Load'!$C$4:$C$35,'System Load'!$A$4:$A$35),_xlfn.XLOOKUP($F31,'System Load'!$G$2:$J$2,'System Load'!$G$1:$J$1)))} -> 1 | W31: {=IF($F31<=5,1,INDEX('System Load'!$G$4:$J$35,_xlfn.XLOOKUP('Renewable Dispatch'!W$3,'System Load'!$C$4:$C$35,'System Load'!$A$4:$A$35),_xlfn.XLOOKUP($F31,'System Load'!$G$2:$J$2,'System Load'!$G$1:$J$1)))} -> 1
A32: Central Washington Power | B32: 5 | C32: 51 | D32: East | E32: =Portfolios!E29 -> Nuclear | F32: =_xlfn.XLOOKUP(E32,'System Load'!$P$7:$P$15,'System Load'!$Q$7:$Q$15) -> 5 | G32: =Portfolios!F29 -> 1100 | J32: =Bids!G31 -> 0 | K32: =Bids!I31 -> 0 | L32: =Bids!K31 -> 0 | M32: =Bids!M31 -> 0 | O32: =Bids!H31+RAND()/100 -> 0.0033837929 | P32: =Bids!J31+RAND()/100 -> 0.0029464811 | Q32: =Bids!L31+RAND()/100 -> 0.0017450876 | R32: =Bids!N31+RAND()/100 -> 0.0064892876 | T32: {=IF($F32<=5,1,INDEX('System Load'!$G$4:$J$35,_xlfn.XLOOKUP('Renewable Dispatch'!T$3,'System Load'!$C$4:$C$35,'System Load'!$A$4:$A$35),_xlfn.XLOOKUP($F32,'System Load'!$G$2:$J$2,'System Load'!$G$1:$J$1)))} -> 1 | U32: {=IF($F32<=5,1,INDEX('System Load'!$G$4:$J$35,_xlfn.XLOOKUP('Renewable Dispatch'!U$3,'System Load'!$C$4:$C$35,'System Load'!$A$4:$A$35),_xlfn.XLOOKUP($F32,'System Load'!$G$2:$J$2,'System Load'!$G$1:$J$1)))} -> 1 | V32: {=IF($F32<=5,1,INDEX('System Load'!$G$4:$J$35,_xlfn.XLOOKUP('Renewable Dispatch'!V$3,'System Load'!$C$4:$C$35,'System Load'!$A$4:$A$35),_xlfn.XLOOKUP($F32,'System Load'!$G$2:$J$2,'System Load'!$G$1:$J$1)))} -> 1 | W32: {=IF($F32<=5,1,INDEX('System Load'!$G$4:$J$35,_xlfn.XLOOKUP('Renewable Dispatch'!W$3,'System Load'!$C$4:$C$35,'System Load'!$A$4:$A$35),_xlfn.XLOOKUP($F32,'System Load'!$G$2:$J$2,'System Load'!$G$1:$J$1)))} -> 1
B33: 5 | C33: 52 | D33: East | E33: =Portfolios!E30 -> Nuclear | F33: =_xlfn.XLOOKUP(E33,'System Load'!$P$7:$P$15,'System Load'!$Q$7:$Q$15) -> 5 | G33: =Portfolios!F30 -> 950 | J33: =Bids!G32 -> 0 | K33: =Bids!I32 -> 0 | L33: =Bids!K32 -> 0 | M33: =Bids!M32 -> 0 | O33: =Bids!H32+RAND()/100 -> 0.00068073076 | P33: =Bids!J32+RAND()/100 -> 0.0096065463 | Q33: =Bids!L32+RAND()/100 -> 0.0096716238 | R33: =Bids!N32+RAND()/100 -> 0.0020910587 | T33: {=IF($F33<=5,1,INDEX('System Load'!$G$4:$J$35,_xlfn.XLOOKUP('Renewable Dispatch'!T$3,'System Load'!$C$4:$C$35,'System Load'!$A$4:$A$35),_xlfn.XLOOKUP($F33,'System Load'!$G$2:$J$2,'System Load'!$G$1:$J$1)))} -> 1 | U33: {=IF($F33<=5,1,INDEX('System Load'!$G$4:$J$35,_xlfn.XLOOKUP('Renewable Dispatch'!U$3,'System Load'!$C$4:$C$35,'System Load'!$A$4:$A$35),_xlfn.XLOOKUP($F33,'System Load'!$G$2:$J$2,'System Load'!$G$1:$J$1)))} -> 1 | V33: {=IF($F33<=5,1,INDEX('System Load'!$G$4:$J$35,_xlfn.XLOOKUP('Renewable Dispatch'!V$3,'System Load'!$C$4:$C$35,'System Load'!$A$4:$A$35),_xlfn.XLOOKUP($F33,'System Load'!$G$2:$J$2,'System Load'!$G$1:$J$1)))} -> 1 | W33: {=IF($F33<=5,1,INDEX('System Load'!$G$4:$J$35,_xlfn.XLOOKUP('Renewable Dispatch'!W$3,'System Load'!$C$4:$C$35,'System Load'!$A$4:$A$35),_xlfn.XLOOKUP($F33,'System Load'!$G$2:$J$2,'System Load'!$G$1:$J$1)))} -> 1
B34: 5 | C34: 53 | D34: East | E34: =Portfolios!E31 -> Hydro | F34: =_xlfn.XLOOKUP(E34,'System Load'!$P$7:$P$15,'System Load'!$Q$7:$Q$15) -> 3 | G34: =Portfolios!F31 -> 650 | J34: =Bids!G33 -> 0 | K34: =Bids!I33 -> 0 | L34: =Bids!K33 -> 0 | M34: =Bids!M33 -> 0 | O34: =Bids!H33+RAND()/100 -> 0.0051276766 | P34: =Bids!J33+RAND()/100 -> 0.0061727982 | Q34: =Bids!L33+RAND()/100 -> 0.0026926938 | R34: =Bids!N33+RAND()/100 -> 0.0084194157 | T34: {=IF($F34<=5,1,INDEX('System Load'!$G$4:$J$35,_xlfn.XLOOKUP('Renewable Dispatch'!T$3,'System Load'!$C$4:$C$35,'System Load'!$A$4:$A$35),_xlfn.XLOOKUP($F34,'System Load'!$G$2:$J$2,'System Load'!$G$1:$J$1)))} -> 1 | U34: {=IF($F34<=5,1,INDEX('System Load'!$G$4:$J$35,_xlfn.XLOOKUP('Renewable Dispatch'!U$3,'System Load'!$C$4:$C$35,'System Load'!$A$4:$A$35),_xlfn.XLOOKUP($F34,'System Load'!$G$2:$J$2,'System Load'!$G$1:$J$1)))} -> 1 | V34: {=IF($F34<=5,1,INDEX('System Load'!$G$4:$J$35,_xlfn.XLOOKUP('Renewable Dispatch'!V$3,'System Load'!$C$4:$C$35,'System Load'!$A$4:$A$35),_xlfn.XLOOKUP($F34,'System Load'!$G$2:$J$2,'System Load'!$G$1:$J$1)))} -> 1 | W34: {=IF($F34<=5,1,INDEX('System Load'!$G$4:$J$35,_xlfn.XLOOKUP('Renewable Dispatch'!W$3,'System Load'!$C$4:$C$35,'System Load'!$A$4:$A$35),_xlfn.XLOOKUP($F34,'System Load'!$G$2:$J$2,'System Load'!$G$1:$J$1)))} -> 1
B35: 5 | C35: 54 | D35: East | E35: =Portfolios!E32 -> Hydro | F35: =_xlfn.XLOOKUP(E35,'System Load'!$P$7:$P$15,'System Load'!$Q$7:$Q$15) -> 3 | G35: =Portfolios!F32 -> 450 | J35: =Bids!G34 -> 0 | K35: =Bids!I34 -> 0 | L35: =Bids!K34 -> 0 | M35: =Bids!M34 -> 0 | O35: =Bids!H34+RAND()/100 -> 0.0076037935 | P35: =Bids!J34+RAND()/100 -> 0.0030881476 | Q35: =Bids!L34+RAND()/100 -> 0.0049277947 | R35: =Bids!N34+RAND()/100 -> 0.0045676264 | T35: {=IF($F35<=5,1,INDEX('System Load'!$G$4:$J$35,_xlfn.XLOOKUP('Renewable Dispatch'!T$3,'System Load'!$C$4:$C$35,'System Load'!$A$4:$A$35),_xlfn.XLOOKUP($F35,'System Load'!$G$2:$J$2,'System Load'!$G$1:$J$1)))} -> 1 | U35: {=IF($F35<=5,1,INDEX('System Load'!$G$4:$J$35,_xlfn.XLOOKUP('Renewable Dispatch'!U$3,'System Load'!$C$4:$C$35,'System Load'!$A$4:$A$35),_xlfn.XLOOKUP($F35,'System Load'!$G$2:$J$2,'System Load'!$G$1:$J$1)))} -> 1 | V35: {=IF($F35<=5,1,INDEX('System Load'!$G$4:$J$35,_xlfn.XLOOKUP('Renewable Dispatch'!V$3,'System Load'!$C$4:$C$35,'System Load'!$A$4:$A$35),_xlfn.XLOOKUP($F35,'System Load'!$G$2:$J$2,'System Load'!$G$1:$J$1)))} -> 1 | W35: {=IF($F35<=5,1,INDEX('System Load'!$G$4:$J$35,_xlfn.XLOOKUP('Renewable Dispatch'!W$3,'System Load'!$C$4:$C$35,'System Load'!$A$4:$A$35),_xlfn.XLOOKUP($F35,'System Load'!$G$2:$J$2,'System Load'!$G$1:$J$1)))} -> 1
B36: 5 | C36: 55 | D36: East | E36: =Portfolios!E33 -> Onshore Wind | F36: =_xlfn.XLOOKUP(E36,'System Load'!$P$7:$P$15,'System Load'!$Q$7:$Q$15) -> 7 | G36: =Portfolios!F33 -> 400 | J36: =Bids!G35 -> 0 | K36: =Bids!I35 -> 0 | L36: =Bids!K35 -> 0 | M36: =Bids!M35 -> 0 | O36: =Bids!H35+RAND()/100 -> 0.0092597348 | P36: =Bids!J35+RAND()/100 -> 0.0011400849 | Q36: =Bids!L35+RAND()/100 -> 0.00078324351 | R36: =Bids!N35+RAND()/100 -> 0.0065949851 | T36: {=IF($F36<=5,1,INDEX('System Load'!$G$4:$J$35,_xlfn.XLOOKUP('Renewable Dispatch'!T$3,'System Load'!$C$4:$C$35,'System Load'!$A$4:$A$35),_xlfn.XLOOKUP($F36,'System Load'!$G$2:$J$2,'System Load'!$G$1:$J$1)))} -> 0.055797368 | U36: {=IF($F36<=5,1,INDEX('System Load'!$G$4:$J$35,_xlfn.XLOOKUP('Renewable Dispatch'!U$3,'System Load'!$C$4:$C$35,'System Load'!$A$4:$A$35),_xlfn.XLOOKUP($F36,'System Load'!$G$2:$J$2,'System Load'!$G$1:$J$1)))} -> 0.70863205 | V36: {=IF($F36<=5,1,INDEX('System Load'!$G$4:$J$35,_xlfn.XLOOKUP('Renewable Dispatch'!V$3,'System Load'!$C$4:$C$35,'System Load'!$A$4:$A$35),_xlfn.XLOOKUP($F36,'System Load'!$G$2:$J$2,'System Load'!$G$1:$J$1)))} -> 0.4494775 | W36: {=IF($F36<=5,1,INDEX('System Load'!$G$4:$J$35,_xlfn.XLOOKUP('Renewable Dispatch'!W$3,'System Load'!$C$4:$C$35,'System Load'!$A$4:$A$35),_xlfn.XLOOKUP($F36,'System Load'!$G$2:$J$2,'System Load'!$G$1:$J$1)))} -> 0.11977743
A37: Snake River Energy | B37: 6 | C37: 61 | D37: East | E37: =Portfolios!E34 -> Solar | F37: =_xlfn.XLOOKUP(E37,'System Load'!$P$7:$P$15,'System Load'!$Q$7:$Q$15) -> 8 | G37: =Portfolios!F34 -> 950 | J37: =Bids!G36 -> 0 | K37: =Bids!I36 -> 0 | L37: =Bids!K36 -> 0 | M37: =Bids!M36 -> 0 | O37: =Bids!H36+RAND()/100 -> 0.0078976283 | P37: =Bids!J36+RAND()/100 -> 0.0051069236 | Q37: =Bids!L36+RAND()/100 -> 0.0033326119 | R37: =Bids!N36+RAND()/100 -> 0.0099340392 | T37: {=IF($F37<=5,1,INDEX('System Load'!$G$4:$J$35,_xlfn.XLOOKUP('Renewable Dispatch'!T$3,'System Load'!$C$4:$C$35,'System Load'!$A$4:$A$35),_xlfn.XLOOKUP($F37,'System Load'!$G$2:$J$2,'System Load'!$G$1:$J$1)))} -> 0.44438288 | U37: {=IF($F37<=5,1,INDEX('System Load'!$G$4:$J$35,_xlfn.XLOOKUP('Renewable Dispatch'!U$3,'System Load'!$C$4:$C$35,'System Load'!$A$4:$A$35),_xlfn.XLOOKUP($F37,'System Load'!$G$2:$J$2,'System Load'!$G$1:$J$1)))} -> 1 | V37: {=IF($F37<=5,1,INDEX('System Load'!$G$4:$J$35,_xlfn.XLOOKUP('Renewable Dispatch'!V$3,'System Load'!$C$4:$C$35,'System Load'!$A$4:$A$35),_xlfn.XLOOKUP($F37,'System Load'!$G$2:$J$2,'System Load'!$G$1:$J$1)))} -> 0.79116936 | W37: {=IF($F37<=5,1,INDEX('System Load'!$G$4:$J$35,_xlfn.XLOOKUP('Renewable Dispatch'!W$3,'System Load'!$C$4:$C$35,'System Load'!$A$4:$A$35),_xlfn.XLOOKUP($F37,'System Load'!$G$2:$J$2,'System Load'!$G$1:$J$1)))} -> 0.23501107
B38: 6 | C38: 62 | D38: East | E38: =Portfolios!E35 -> Solar | F38: =_xlfn.XLOOKUP(E38,'System Load'!$P$7:$P$15,'System Load'!$Q$7:$Q$15) -> 8 | G38: =Portfolios!F35 -> 875 | J38: =Bids!G37 -> 0 | K38: =Bids!I37 -> 0 | L38: =Bids!K37 -> 0 | M38: =Bids!M37 -> 0 | O38: =Bids!H37+RAND()/100 -> 0.0095276108 | P38: =Bids!J37+RAND()/100 -> 0.0012558235 | Q38: =Bids!L37+RAND()/100 -> 0.00081831892 | R38: =Bids!N37+RAND()/100 -> 0.0033054018 | T38: {=IF($F38<=5,1,INDEX('System Load'!$G$4:$J$35,_xlfn.XLOOKUP('Renewable Dispatch'!T$3,'System Load'!$C$4:$C$35,'System Load'!$A$4:$A$35),_xlfn.XLOOKUP($F38,'System Load'!$G$2:$J$2,'System Load'!$G$1:$J$1)))} -> 0.44438288 | U38: {=IF($F38<=5,1,INDEX('System Load'!$G$4:$J$35,_xlfn.XLOOKUP('Renewable Dispatch'!U$3,'System Load'!$C$4:$C$35,'System Load'!$A$4:$A$35),_xlfn.XLOOKUP($F38,'System Load'!$G$2:$J$2,'System Load'!$G$1:$J$1)))} -> 1 | V38: {=IF($F38<=5,1,INDEX('System Load'!$G$4:$J$35,_xlfn.XLOOKUP('Renewable Dispatch'!V$3,'System Load'!$C$4:$C$35,'System Load'!$A$4:$A$35),_xlfn.XLOOKUP($F38,'System Load'!$G$2:$J$2,'System Load'!$G$1:$J$1)))} -> 0.79116936 | W38: {=IF($F38<=5,1,INDEX('System Load'!$G$4:$J$35,_xlfn.XLOOKUP('Renewable Dispatch'!W$3,'System Load'!$C$4:$C$35,'System Load'!$A$4:$A$35),_xlfn.XLOOKUP($F38,'System Load'!$G$2:$J$2,'System Load'!$G$1:$J$1)))} -> 0.23501107
B39: 6 | C39: 63 | D39: East | E39: =Portfolios!E36 -> Hydro | F39: =_xlfn.XLOOKUP(E39,'System Load'!$P$7:$P$15,'System Load'!$Q$7:$Q$15) -> 3 | G39: =Portfolios!F36 -> 300 | J39: =Bids!G38 -> 0 | K39: =Bids!I38 -> 0 | L39: =Bids!K38 -> 0 | M39: =Bids!M38 -> 0 | O39: =Bids!H38+RAND()/100 -> 0.0084949299 | P39: =Bids!J38+RAND()/100 -> 0.0042959336 | Q39: =Bids!L38+RAND()/100 -> 0.005356565 | R39: =Bids!N38+RAND()/100 -> 0.0052181475 | T39: {=IF($F39<=5,1,INDEX('System Load'!$G$4:$J$35,_xlfn.XLOOKUP('Renewable Dispatch'!T$3,'System Load'!$C$4:$C$35,'System Load'!$A$4:$A$35),_xlfn.XLOOKUP($F39,'System Load'!$G$2:$J$2,'System Load'!$G$1:$J$1)))} -> 1 | U39: {=IF($F39<=5,1,INDEX('System Load'!$G$4:$J$35,_xlfn.XLOOKUP('Renewable Dispatch'!U$3,'System Load'!$C$4:$C$35,'System Load'!$A$4:$A$35),_xlfn.XLOOKUP($F39,'System Load'!$G$2:$J$2,'System Load'!$G$1:$J$1)))} -> 1 | V39: {=IF($F39<=5,1,INDEX('System Load'!$G$4:$J$35,_xlfn.XLOOKUP('Renewable Dispatch'!V$3,'System Load'!$C$4:$C$35,'System Load'!$A$4:$A$35),_xlfn.XLOOKUP($F39,'System Load'!$G$2:$J$2,'System Load'!$G$1:$J$1)))} -> 1 | W39: {=IF($F39<=5,1,INDEX('System Load'!$G$4:$J$35,_xlfn.XLOOKUP('Renewable Dispatch'!W$3,'System Load'!$C$4:$C$35,'System Load'!$A$4:$A$35),_xlfn.XLOOKUP($F39,'System Load'!$G$2:$J$2,'System Load'!$G$1:$J$1)))} -> 1
